Workbook

Sheet Instrucciones
A1: Matriz de validación de descripciones de columnas · SuperApp ESAP · Base completa
A2: Base esap_db (QA) · extracción del 2026-10-22 · generada el 2026-10-22
A4: Objetivo
A5: Revisar con el equipo de desarrollo la descripción de cada columna que aún no tiene descripción registrada en la base ni validada.
A6: Las propuestas se redactaron a partir de la estructura (nombre, tipo, restricciones, valores permitidos, relaciones) y del código de las funciones, triggers y vistas que usan la columna, y del código fuente de la aplicación (entidades y migraciones). No se revisaron valores de los registros. Son propuestas: no reemplazan el conocimiento del equipo.
A8: Cómo revisar (hoja «Matriz»)
A9: 1. Lea la propuesta, su fundamento y, si la hay, la pregunta para desarrollo.
A10: 2. Elija la decisión en la lista desplegable (celdas amarillas):
A11: Aprobada: la propuesta se registra tal cual.
A12: Aprobada con ajuste: escriba el texto correcto en «Descripción final».
A13: Rechazada: la propuesta no corresponde; escriba la descripción correcta en «Descripción final» o explique en «Observaciones».
A14: Requiere aclaración: falta información; anote la duda en «Observaciones».
... A28: Las validadas se publican en el portal y quedan listas para registrarse en la base con un lote COMMENT ON (con reversa), cuando haya autorización.

Sheet Métricas
A1: Métricas de la revisión · Base completa
A3: Avance general
A4: Indicador | B4: Valor
A5: Columnas en la matriz | B5: =COUNTA(Matriz!$A$2:$A$3626) -> 3625
A6: Pendiente | B6: =COUNTIF(Matriz!$V$2:$V$3626,"Pendiente") -> 3625
A7: Aprobada | B7: =COUNTIF(Matriz!$V$2:$V$3626,"Aprobada") -> 0
A8: Aprobada con ajuste | B8: =COUNTIF(Matriz!$V$2:$V$3626,"Aprobada con ajuste") -> 0
A9: Rechazada | B9: =COUNTIF(Matriz!$V$2:$V$3626,"Rechazada") -> 0
A10: Requiere aclaración | B10: =COUNTIF(Matriz!$V$2:$V$3626,"Requiere aclaración") -> 0
A11: Revisadas (decisión distinta de Pendiente) | B11: =B5-B6 -> 0
A12: % revisado | B12: =IF(B5=0,0,B11/B5) -> 0
A13: Con descripción a registrar | B13: =SUMPRODUCT(--(Matriz!$AA$2:$AA$3626<>"")) -> 0
A14: Ajustes sin texto en «Descripción final» | B14: =SUMPRODUCT(((Matriz!$V$2:$V$3626="Aprobada con ajuste")+(Matriz!$V$2:$V$3626="Rechazada"))*(Matriz!$W$2:$W$3626="")) -> 0
A16: Cobertura de descripciones de columnas (indicador K02, meta ≥ 95 %)
A17: Concepto | B17: Valor
A18: Columnas del alcance | B18: 5700
A19: Con descripción registrada en la base (COMMENT) | B19: 604
A20: Validadas antes de esta matriz (config/descripciones.csv) | B20: 1471
A21: Con descripción a registrar en esta matriz | B21: =B13 -> 0
A22: Cobertura actual | B22: =(B19+B20)/B18 -> 0.36403509
A23: Cobertura al incorporar la matriz | B23: =(B19+B20+B21)/B18 -> 0.36403509
A24: Columnas que faltan para la meta de 95 % | B24: =MAX(0,ROUNDUP(0.95*B18,0)-(B19+B20+B21)) -> 3340
A25: Columnas del alcance, base y validadas: cifras fijas de la extracción del 2026-10-22 y de config/descripciones.csv.
A27: Avance por dominio
A28: Dominio | B28: Esquema | C28: Columnas | D28: Aprobadas | E28: Rechazadas | F28: Por aclarar | G28: Pendientes | H28: % revisado
A29: Identidad y acceso | B29: auth | C29: =COUNTIF(Matriz!$C$2:$C$3626,B29) -> 188 | D29: =COUNTIFS(Matriz!$C$2:$C$3626,B29,Matriz!$V$2:$V$3626,"Aprobada")+COUNTIFS(Matriz!$C$2:$C$3626,B29,Matriz!$V$2:$V$3626,"Aprobada con ajuste") -> 0 | E29: =COUNTIFS(Matriz!$C$2:$C$3626,B29,Matriz!$V$2:$V$3626,"Rechazada") -> 0 | F29: =COUNTIFS(Matriz!$C$2:$C$3626,B29,Matriz!$V$2:$V$3626,"Requiere aclaración") -> 0 | G29: =COUNTIFS(Matriz!$C$2:$C$3626,B29,Matriz!$V$2:$V$3626,"Pendiente") -> 188 | H29: =IF(C29=0,0,(C29-G29)/C29) -> 0
A30: Registro académico | B30: academic_registration | C30: =COUNTIF(Matriz!$C$2:$C$3626,B30) -> 124 | D30: =COUNTIFS(Matriz!$C$2:$C$3626,B30,Matriz!$V$2:$V$3626,"Aprobada")+COUNTIFS(Matriz!$C$2:$C$3626,B30,Matriz!$V$2:$V$3626,"Aprobada con ajuste") -> 0 | E30: =COUNTIFS(Matriz!$C$2:$C$3626,B30,Matriz!$V$2:$V$3626,"Rechazada") -> 0 | F30: =COUNTIFS(Matriz!$C$2:$C$3626,B30,Matriz!$V$2:$V$3626,"Requiere aclaración") -> 0 | G30: =COUNTIFS(Matriz!$C$2:$C$3626,B30,Matriz!$V$2:$V$3626,"Pendiente") -> 124 | H30: =IF(C30=0,0,(C30-G30)/C30) -> 0
A31: Plan de trabajo académico | B31: academic_work_plan | C31: =COUNTIF(Matriz!$C$2:$C$3626,B31) -> 512 | D31: =COUNTIFS(Matriz!$C$2:$C$3626,B31,Matriz!$V$2:$V$3626,"Aprobada")+COUNTIFS(Matriz!$C$2:$C$3626,B31,Matriz!$V$2:$V$3626,"Aprobada con ajuste") -> 0 | E31: =COUNTIFS(Matriz!$C$2:$C$3626,B31,Matriz!$V$2:$V$3626,"Rechazada") -> 0 | F31: =COUNTIFS(Matriz!$C$2:$C$3626,B31,Matriz!$V$2:$V$3626,"Requiere aclaración") -> 0 | G31: =COUNTIFS(Matriz!$C$2:$C$3626,B31,Matriz!$V$2:$V$3626,"Pendiente") -> 512 | H31: =IF(C31=0,0,(C31-G31)/C31) -> 0
A32: Certificaciones | B32: certification | C32: =COUNTIF(Matriz!$C$2:$C$3626,B32) -> 107 | D32: =COUNTIFS(Matriz!$C$2:$C$3626,B32,Matriz!$V$2:$V$3626,"Aprobada")+COUNTIFS(Matriz!$C$2:$C$3626,B32,Matriz!$V$2:$V$3626,"Aprobada con ajuste") -> 0 | E32: =COUNTIFS(Matriz!$C$2:$C$3626,B32,Matriz!$V$2:$V$3626,"Rechazada") -> 0 | F32: =COUNTIFS(Matriz!$C$2:$C$3626,B32,Matriz!$V$2:$V$3626,"Requiere aclaración") -> 0 | G32: =COUNTIFS(Matriz!$C$2:$C$3626,B32,Matriz!$V$2:$V$3626,"Pendiente") -> 107 | H32: =IF(C32=0,0,(C32-G32)/C32) -> 0
A33: Gestión jurídica | B33: legal_management | C33: =COUNTIF(Matriz!$C$2:$C$3626,B33) -> 547 | D33: =COUNTIFS(Matriz!$C$2:$C$3626,B33,Matriz!$V$2:$V$3626,"Aprobada")+COUNTIFS(Matriz!$C$2:$C$3626,B33,Matriz!$V$2:$V$3626,"Aprobada con ajuste") -> 0 | E33: =COUNTIFS(Matriz!$C$2:$C$3626,B33,Matriz!$V$2:$V$3626,"Rechazada") -> 0 | F33: =COUNTIFS(Matriz!$C$2:$C$3626,B33,Matriz!$V$2:$V$3626,"Requiere aclaración") -> 0 | G33: =COUNTIFS(Matriz!$C$2:$C$3626,B33,Matriz!$V$2:$V$3626,"Pendiente") -> 547 | H33: =IF(C33=0,0,(C33-G33)/C33) -> 0
A34: Control interno | B34: control_interno | C34: =COUNTIF(Matriz!$C$2:$C$3626,B34) -> 805 | D34: =COUNTIFS(Matriz!$C$2:$C$3626,B34,Matriz!$V$2:$V$3626,"Aprobada")+COUNTIFS(Matriz!$C$2:$C$3626,B34,Matriz!$V$2:$V$3626,"Aprobada con ajuste") -> 0 | E34: =COUNTIFS(Matriz!$C$2:$C$3626,B34,Matriz!$V$2:$V$3626,"Rechazada") -> 0 | F34: =COUNTIFS(Matriz!$C$2:$C$3626,B34,Matriz!$V$2:$V$3626,"Requiere aclaración") -> 0 | G34: =COUNTIFS(Matriz!$C$2:$C$3626,B34,Matriz!$V$2:$V$3626,"Pendiente") -> 805 | H34: =IF(C34=0,0,(C34-G34)/C34) -> 0
A35: Control disciplinario interno | B35: internal_disciplinary_control | C35: =COUNTIF(Matriz!$C$2:$C$3626,B35) -> 206 | D35: =COUNTIFS(Matriz!$C$2:$C$3626,B35,Matriz!$V$2:$V$3626,"Aprobada")+COUNTIFS(Matriz!$C$2:$C$3626,B35,Matriz!$V$2:$V$3626,"Aprobada con ajuste") -> 0 | E35: =COUNTIFS(Matriz!$C$2:$C$3626,B35,Matriz!$V$2:$V$3626,"Rechazada") -> 0 | F35: =COUNTIFS(Matriz!$C$2:$C$3626,B35,Matriz!$V$2:$V$3626,"Requiere aclaración") -> 0 | G35: =COUNTIFS(Matriz!$C$2:$C$3626,B35,Matriz!$V$2:$V$3626,"Pendiente") -> 206 | H35: =IF(C35=0,0,(C35-G35)/C35) -> 0
A36: Requerimientos | B36: requerimientos_oc | C36: =COUNTIF(Matriz!$C$2:$C$3626,B36) -> 70 | D36: =COUNTIFS(Matriz!$C$2:$C$3626,B36,Matriz!$V$2:$V$3626,"Aprobada")+COUNTIFS(Matriz!$C$2:$C$3626,B36,Matriz!$V$2:$V$3626,"Aprobada con ajuste") -> 0 | E36: =COUNTIFS(Matriz!$C$2:$C$3626,B36,Matriz!$V$2:$V$3626,"Rechazada") -> 0 | F36: =COUNTIFS(Matriz!$C$2:$C$3626,B36,Matriz!$V$2:$V$3626,"Requiere aclaración") -> 0 | G36: =COUNTIFS(Matriz!$C$2:$C$3626,B36,Matriz!$V$2:$V$3626,"Pendiente") -> 70 | H36: =IF(C36=0,0,(C36-G36)/C36) -> 0
A37: Notificaciones | B37: notifications | C37: =COUNTIF(Matriz!$C$2:$C$3626,B37) -> 24 | D37: =COUNTIFS(Matriz!$C$2:$C$3626,B37,Matriz!$V$2:$V$3626,"Aprobada")+COUNTIFS(Matriz!$C$2:$C$3626,B37,Matriz!$V$2:$V$3626,"Aprobada con ajuste") -> 0 | E37: =COUNTIFS(Matriz!$C$2:$C$3626,B37,Matriz!$V$2:$V$3626,"Rechazada") -> 0 | F37: =COUNTIFS(Matriz!$C$2:$C$3626,B37,Matriz!$V$2:$V$3626,"Requiere aclaración") -> 0 | G37: =COUNTIFS(Matriz!$C$2:$C$3626,B37,Matriz!$V$2:$V$3626,"Pendiente") -> 24 | H37: =IF(C37=0,0,(C37-G37)/C37) -> 0
A38: Auditoría y trazabilidad | B38: audit | C38: =COUNTIF(Matriz!$C$2:$C$3626,B38) -> 23 | D38: =COUNTIFS(Matriz!$C$2:$C$3626,B38,Matriz!$V$2:$V$3626,"Aprobada")+COUNTIFS(Matriz!$C$2:$C$3626,B38,Matriz!$V$2:$V$3626,"Aprobada con ajuste") -> 0 | E38: =COUNTIFS(Matriz!$C$2:$C$3626,B38,Matriz!$V$2:$V$3626,"Rechazada") -> 0 | F38: =COUNTIFS(Matriz!$C$2:$C$3626,B38,Matriz!$V$2:$V$3626,"Requiere aclaración") -> 0 | G38: =COUNTIFS(Matriz!$C$2:$C$3626,B38,Matriz!$V$2:$V$3626,"Pendiente") -> 23 | H38: =IF(C38=0,0,(C38-G38)/C38) -> 0
A39: Esquema público | B39: public | C39: =COUNTIF(Matriz!$C$2:$C$3626,B39) -> 14 | D39: =COUNTIFS(Matriz!$C$2:$C$3626,B39,Matriz!$V$2:$V$3626,"Aprobada")+COUNTIFS(Matriz!$C$2:$C$3626,B39,Matriz!$V$2:$V$3626,"Aprobada con ajuste") -> 0 | E39: =COUNTIFS(Matriz!$C$2:$C$3626,B39,Matriz!$V$2:$V$3626,"Rechazada") -> 0 | F39: =COUNTIFS(Matriz!$C$2:$C$3626,B39,Matriz!$V$2:$V$3626,"Requiere aclaración") -> 0 | G39: =COUNTIFS(Matriz!$C$2:$C$3626,B39,Matriz!$V$2:$V$3626,"Pendiente") -> 14 | H39: =IF(C39=0,0,(C39-G39)/C39) -> 0
A40: Programación académica | B40: academic-schedule | C40: =COUNTIF(Matriz!$C$2:$C$3626,B40) -> 93 | D40: =COUNTIFS(Matriz!$C$2:$C$3626,B40,Matriz!$V$2:$V$3626,"Aprobada")+COUNTIFS(Matriz!$C$2:$C$3626,B40,Matriz!$V$2:$V$3626,"Aprobada con ajuste") -> 0 | E40: =COUNTIFS(Matriz!$C$2:$C$3626,B40,Matriz!$V$2:$V$3626,"Rechazada") -> 0 | F40: =COUNTIFS(Matriz!$C$2:$C$3626,B40,Matriz!$V$2:$V$3626,"Requiere aclaración") -> 0 | G40: =COUNTIFS(Matriz!$C$2:$C$3626,B40,Matriz!$V$2:$V$3626,"Pendiente") -> 93 | H40: =IF(C40=0,0,(C40-G40)/C40) -> 0
... A44: Asistente virtual (chatbot) | B44: chatbot | C44: =COUNTIF(Matriz!$C$2:$C$3626,B44) -> 16 | D44: =COUNTIFS(Matriz!$C$2:$C$3626,B44,Matriz!$V$2:$V$3626,"Aprobada")+COUNTIFS(Matriz!$C$2:$C$3626,B44,Matriz!$V$2:$V$3626,"Aprobada con ajuste") -> 0 | E44: =COUNTIFS(Matriz!$C$2:$C$3626,B44,Matriz!$V$2:$V$3626,"Rechazada") -> 0 | F44: =COUNTIFS(Matriz!$C$2:$C$3626,B44,Matriz!$V$2:$V$3626,"Requiere aclaración") -> 0 | G44: =COUNTIFS(Matriz!$C$2:$C$3626,B44,Matriz!$V$2:$V$3626,"Pendiente") -> 16 | H44: =IF(C44=0,0,(C44-G44)/C44) -> 0
A45: Total | C45: =SUM(C29:C44) -> 3625 | D45: =SUM(D29:D44) -> 0 | E45: =SUM(E29:E44) -> 0 | F45: =SUM(F29:F44) -> 0 | G45: =SUM(G29:G44) -> 3625 | H45: =IF(C45=0,0,(C45-G45)/C45) -> 0
A47: Avance por confianza y origen de la propuesta
...

Sheet Matriz
A1: ID | B1: Dominio | C1: Esquema | D1: Tabla | E1: Filas en QA | F1: Columna | G1: Tipo de dato | H1: Admite nulos | I1: Restricciones | J1: Valores permitidos | K1: Referencia (FK) | L1: Catálogo | M1: Uso en lógica | N1: Detalle del uso | O1: Índices | P1: Evidencia en código | Q1: Origen | R1: Propuesta de descripción | S1: Confianza | T1: Fundamento | U1: Pregunta para desarrollo | V1: Decisión | W1: Descripción final | X1: Revisado por | Y1: Fecha de revisión | Z1: Observaciones | AA1: Descripción a registrar
A2: C0001 | B2: Identidad y acceso | C2: auth | D2: acreditaciones_programa | E2: 5 | F2: tipo | G2: text | H2: No | L2: No | M2: No | P2: db/migrations/old/006_create_programas_academicos.sql:49: Alta Calidad, Internacional, etc. | Q2: Código fuente | R2: Tipo de acreditación del programa académico (por ejemplo, Alta Calidad, Internacional). | S2: Alta | T2: código: db/migrations/old/006_create_programas_academicos.sql:49 | V2: Pendiente | AA2: =IF(OR(V2="Aprobada"),R2,IF(AND(OR(V2="Aprobada con ajuste",V2="Rechazada"),W2<>""),W2,""))
A3: C0002 | B3: Identidad y acceso | C3: auth | D3: acreditaciones_programa | E3: 5 | F3: vigencia | G3: date | H3: No | L3: No | M3: No | Q3: Regla estructural | R3: Vigencia (año). | S3: Media | T3: Convención de nombre de la columna. | V3: Pendiente | AA3: =IF(OR(V3="Aprobada"),R3,IF(AND(OR(V3="Aprobada con ajuste",V3="Rechazada"),W3<>""),W3,""))
A4: C0003 | B4: Identidad y acceso | C4: auth | D4: cargos | E4: 17 | F4: cod_cargo | G4: character varying(50) | H4: No | I4: Única | L4: No | M4: No | O4: cargos_cod_cargo_key, idx_cargos_codigo | P4: Mapeada en auth-service/src/users/cargo.entity.ts:19 (Cargo.codCargo) | Validación: IsString, MaxLength(50, { message: 'El código de cargo no puede exceder 50 caracteres' }) | Q4: Propuesta semántica | R4: Código del cargo; es único en la tabla (máximo 50 caracteres). | S4: Alta | T4: nombre + tipo + columnas vecinas + restricción única + validaciones | V4: Pendiente | AA4: =IF(OR(V4="Aprobada"),R4,IF(AND(OR(V4="Aprobada con ajuste",V4="Rechazada"),W4<>""),W4,""))
A5: C0004 | B5: Identidad y acceso | C5: auth | D5: cargos | E5: 17 | F5: nom_cargo | G5: character varying(250) | H5: No | L5: No | M5: No | O5: idx_cargos_nombre | P5: Mapeada en auth-service/src/users/cargo.entity.ts:22 (Cargo.nomCargo) | Validación: IsString, MaxLength(250, { message: 'El nombre de cargo no puede exceder 250 caracteres' }) | Q5: Propuesta semántica | R5: Nombre del cargo (máximo 250 caracteres). | S5: Alta | T5: nombre + tipo + columnas vecinas + validaciones | V5: Pendiente | AA5: =IF(OR(V5="Aprobada"),R5,IF(AND(OR(V5="Aprobada con ajuste",V5="Rechazada"),W5<>""),W5,""))
A6: C0005 | B6: Identidad y acceso | C6: auth | D6: cargos | E6: 17 | F6: descripcion | G6: character varying(500) | H6: Sí | L6: No | M6: No | P6: Mapeada en auth-service/src/users/cargo.entity.ts:25 (Cargo.descripcion) | Validación: IsOptional, IsString, MaxLength(150), MaxLength(150, { message: 'La descripción no puede superar 150 caracteres' }), MaxLength(500) | Q6: Regla estructural | R6: Descripción del registro de cargos. | S6: Media | T6: Convención de nombre de la columna. | V6: Pendiente | AA6: =IF(OR(V6="Aprobada"),R6,IF(AND(OR(V6="Aprobada con ajuste",V6="Rechazada"),W6<>""),W6,""))
A7: C0006 | B7: Identidad y acceso | C7: auth | D7: cargos | E7: 17 | F7: nivel_jerarquico | G7: character varying(50) | H7: Sí | L7: No | M7: No | P7: Mapeada en auth-service/src/users/cargo.entity.ts:28 (Cargo.nivelJerarquico) | Validación: IsOptional, IsString, MaxLength(50) | Q7: Propuesta semántica | R7: Nivel jerárquico del cargo. Por defecto, Profesional. | S7: Media | T7: nombre + tipo + columnas vecinas + defecto | U7: ¿Qué valores toma el nivel jerárquico (Directivo, Asesor, Profesional, Técnico, Asistencial)? | V7: Pendiente | AA7: =IF(OR(V7="Aprobada"),R7,IF(AND(OR(V7="Aprobada con ajuste",V7="Rechazada"),W7<>""),W7,""))
A8: C0007 | B8: Identidad y acceso | C8: auth | D8: cargos | E8: 17 | F8: activo | G8: boolean | H8: No | L8: No | M8: No | O8: idx_cargos_activo | P8: Mapeada en auth-service/src/users/cargo.entity.ts:36 (Cargo.activo) | Validación: IsBoolean, IsOptional | Q8: Regla estructural | R8: Indica si el registro está activo. | S8: Media | T8: Convención de nombre de la columna. | V8: Pendiente | AA8: =IF(OR(V8="Aprobada"),R8,IF(AND(OR(V8="Aprobada con ajuste",V8="Rechazada"),W8<>""),W8,""))
A9: C0008 | B9: Identidad y acceso | C9: auth | D9: carpeta_digital | E9: 409 | F9: nombre_carpeta | G9: character varying(255) | H9: Sí | L9: No | M9: No | P9: Mapeada en auth-service/src/carpeta-digital/carpeta-digital.entity.ts:24 (CarpetaDigital.nombreCarpeta) | Q9: Propuesta semántica | R9: Nombre de la carpeta digital de la persona. | S9: Alta | T9: nombre + tipo + columnas vecinas | V9: Pendiente | AA9: =IF(OR(V9="Aprobada"),R9,IF(AND(OR(V9="Aprobada con ajuste",V9="Rechazada"),W9<>""),W9,""))
A10: C0009 | B10: Identidad y acceso | C10: auth | D10: carpeta_digital | E10: 409 | F10: estado | G10: character varying(30) | H10: No | L10: No | M10: No | O10: idx_carpeta_digital_estado | P10: Mapeada en auth-service/src/carpeta-digital/carpeta-digital.entity.ts:27 (CarpetaDigital.estado) | Validación: IsOptional, IsString | Q10: Regla estructural | R10: Estado del registro de carpeta_digital. | S10: Media | T10: Convención de nombre de la columna. | V10: Pendiente | AA10: =IF(OR(V10="Aprobada"),R10,IF(AND(OR(V10="Aprobada con ajuste",V10="Rechazada"),W10<>""),W10,""))
A11: C0010 | B11: Identidad y acceso | C11: auth | D11: carpeta_digital | E11: 409 | F11: metadata | G11: jsonb | H11: Sí | L11: No | M11: No | P11: Mapeada en auth-service/src/carpeta-digital/carpeta-digital.entity.ts:30 (CarpetaDigital.metadata) | Q11: Regla estructural | R11: Metadatos adicionales en formato JSON. | S11: Media | T11: Convención de nombre de la columna. | V11: Pendiente | AA11: =IF(OR(V11="Aprobada"),R11,IF(AND(OR(V11="Aprobada con ajuste",V11="Rechazada"),W11<>""),W11,""))
A12: C0011 | B12: Identidad y acceso | C12: auth | D12: dependencias | E12: 7 | F12: id_empresa | G12: numeric(11,0) | H12: No | L12: No | M12: No | P12: Mapeada en auth-service/src/users/dependencia.entity.ts:52 (Dependencia.idEmpresa) | Q12: Propuesta semántica | R12: Identificador de la empresa o entidad a la que pertenece la dependencia. Por defecto, 1. | S12: Media | T12: nombre + tipo + columnas vecinas + documentación de la entidad | U12: ¿Qué tabla identifica id_empresa y hay más de una empresa registrada? | V12: Pendiente | AA12: =IF(OR(V12="Aprobada"),R12,IF(AND(OR(V12="Aprobada con ajuste",V12="Rechazada"),W12<>""),W12,""))
A13: C0012 | B13: Identidad y acceso | C13: auth | D13: dependencias | E13: 7 | F13: cod_dependencia | G13: character varying(20) | H13: No | I13: Única | L13: No | M13: No | O13: dependencias_cod_dependencia_key | P13: Mapeada en auth-service/src/users/dependencia.entity.ts:55 (Dependencia.codDependencia) | Validación: IsOptional, IsString, MaxLength(20), MaxLength(20, { message: 'El código de dependencia no puede exceder 20 caracteres' }) | Q13: Propuesta semántica | R13: Código de la dependencia; es único en la tabla (máximo 20 caracteres). | S13: Alta | T13: nombre + tipo + columnas vecinas + restricción única + validaciones | V13: Pendiente | AA13: =IF(OR(V13="Aprobada"),R13,IF(AND(OR(V13="Aprobada con ajuste",V13="Rechazada"),W13<>""),W13,""))
A14: C0013 | B14: Identidad y acceso | C14: auth | D14: dependencias | E14: 7 | F14: nom_dependencia | G14: character varying(250) | H14: No | L14: No | M14: No | P14: Mapeada en auth-service/src/users/dependencia.entity.ts:58 (Dependencia.nomDependencia) | Validación: IsOptional, IsString, MaxLength(250), MaxLength(250, { message: 'El nombre de dependencia no puede exceder 250 caracteres' }) | Q14: Propuesta semántica | R14: Nombre de la dependencia (máximo 250 caracteres). | S14: Alta | T14: nombre + tipo + columnas vecinas + validaciones | V14: Pendiente | AA14: =IF(OR(V14="Aprobada"),R14,IF(AND(OR(V14="Aprobada con ajuste",V14="Rechazada"),W14<>""),W14,""))
A15: C0014 | B15: Identidad y acceso | C15: auth | D15: dependencias | E15: 7 | F15: dir_dependencia | G15: character varying(250) | H15: Sí | L15: No | M15: No | P15: Mapeada en auth-service/src/users/dependencia.entity.ts:61 (Dependencia.dirDependencia) | Validación: IsOptional, IsString, MaxLength(250) | Q15: Propuesta semántica | R15: Dirección física de la dependencia. | S15: Media | T15: nombre + tipo + columnas vecinas (dir_email, url_dependencia) | U15: ¿dir_dependencia es la dirección postal de la dependencia? | V15: Pendiente | AA15: =IF(OR(V15="Aprobada"),R15,IF(AND(OR(V15="Aprobada con ajuste",V15="Rechazada"),W15<>""),W15,""))
A16: C0015 | B16: Identidad y acceso | C16: auth | D16: dependencias | E16: 7 | F16: dir_email | G16: character varying(250) | H16: Sí | L16: No | M16: No | P16: Mapeada en auth-service/src/users/dependencia.entity.ts:64 (Dependencia.dirEmail) | Validación: IsEmail, IsEmail({}, { message: 'El email institucional no es válido' }), IsOptional, MaxLength(250) | Q16: Propuesta semántica | R16: Correo electrónico institucional de la dependencia. | S16: Alta | T16: nombre + tipo + columnas vecinas + validación IsEmail | V16: Pendiente | AA16: =IF(OR(V16="Aprobada"),R16,IF(AND(OR(V16="Aprobada con ajuste",V16="Rechazada"),W16<>""),W16,""))
A17: C0016 | B17: Identidad y acceso | C17: auth | D17: dependencias | E17: 7 | F17: url_dependencia | G17: character varying(250) | H17: Sí | L17: No | M17: No | P17: Mapeada en auth-service/src/users/dependencia.entity.ts:67 (Dependencia.urlDependencia) | Validación: IsOptional, IsString, MaxLength(250) | Q17: Propuesta semántica | R17: Dirección web (URL) de la dependencia. | S17: Alta | T17: nombre + tipo + columnas vecinas | V17: Pendiente | AA17: =IF(OR(V17="Aprobada"),R17,IF(AND(OR(V17="Aprobada con ajuste",V17="Rechazada"),W17<>""),W17,""))
A18: C0017 | B18: Identidad y acceso | C18: auth | D18: dependencias | E18: 7 | F18: id_geopolitica | G18: numeric(11,0) | H18: Sí | L18: No | M18: No | P18: Mapeada en auth-service/src/users/dependencia.entity.ts:70 (Dependencia.idGeopolitica) | Validación: IsNumber, IsOptional | Q18: Propuesta semántica | R18: Identificador de la división geopolítica (ciudad o municipio) donde se ubica la dependencia. | S18: Media | T18: nombre + tipo + columnas vecinas (auth.geopolitica) | U18: ¿id_geopolitica referencia a auth.geopolitica.id_geopolitica? | V18: Pendiente | AA18: =IF(OR(V18="Aprobada"),R18,IF(AND(OR(V18="Aprobada con ajuste",V18="Rechazada"),W18<>""),W18,""))
A19: C0018 | B19: Identidad y acceso | C19: auth | D19: dependencias | E19: 7 | F19: id_sede | G19: numeric(11,0) | H19: Sí | L19: No | M19: No | P19: Mapeada en auth-service/src/users/dependencia.entity.ts:73 (Dependencia.idSede) | Validación: IsNumber, IsOptional | Q19: Regla estructural | R19: Referencia al registro de auth.sedes (id_sede); relación sin llave foránea declarada. | S19: Media | T19: Convención de nombre de la columna. | V19: Pendiente | AA19: =IF(OR(V19="Aprobada"),R19,IF(AND(OR(V19="Aprobada con ajuste",V19="Rechazada"),W19<>""),W19,""))
A20: C0019 | B20: Identidad y acceso | C20: auth | D20: dependencias | E20: 7 | F20: id_cargo | G20: numeric(11,0) | H20: Sí | L20: No | M20: No | P20: Mapeada en auth-service/src/users/dependencia.entity.ts:76 (Dependencia.idCargo) | Validación: IsNumber, IsOptional | Q20: Propuesta semántica | R20: Identificador del cargo asociado a la dependencia. | S20: Baja | T20: nombre + tipo + columnas vecinas (auth.cargos) | U20: ¿id_cargo es el cargo del jefe de la dependencia? ¿Referencia a auth.cargos? | V20: Pendiente | AA20: =IF(OR(V20="Aprobada"),R20,IF(AND(OR(V20="Aprobada con ajuste",V20="Rechazada"),W20<>""),W20,""))
A21: C0020 | B21: Identidad y acceso | C21: auth | D21: dependencias | E21: 7 | F21: id_tercero | G21: numeric(11,0) | H21: Sí | L21: No | M21: No | P21: Mapeada en auth-service/src/users/dependencia.entity.ts:79 (Dependencia.idTercero) | Validación: IsNumber, IsOptional | Q21: Propuesta semántica | R21: Identificador del tercero asociado a la dependencia. | S21: Baja | T21: nombre + tipo + columnas vecinas | U21: ¿Qué representa el tercero (responsable de la dependencia) y a qué tabla referencia? | V21: Pendiente | AA21: =IF(OR(V21="Aprobada"),R21,IF(AND(OR(V21="Aprobada con ajuste",V21="Rechazada"),W21<>""),W21,""))
A22: C0021 | B22: Identidad y acceso | C22: auth | D22: dependencias | E22: 7 | F22: tip_unidad | G22: numeric(1,0) | H22: Sí | L22: No | M22: No | P22: Mapeada en auth-service/src/users/dependencia.entity.ts:82 (Dependencia.tipUnidad) | Validación: IsNumber, IsOptional | Q22: Propuesta semántica | R22: Código del tipo de unidad organizacional de la dependencia. | S22: Baja | T22: nombre + tipo + columnas vecinas (gen_tip_unidad) | U22: ¿Qué valores toma tip_unidad y qué significa cada uno? | V22: Pendiente | AA22: =IF(OR(V22="Aprobada"),R22,IF(AND(OR(V22="Aprobada con ajuste",V22="Rechazada"),W22<>""),W22,""))
A23: C0022 | B23: Identidad y acceso | C23: auth | D23: dependencias | E23: 7 | F23: gen_tip_unidad | G23: character varying(6) | H23: Sí | L23: No | M23: No | P23: Mapeada en auth-service/src/users/dependencia.entity.ts:85 (Dependencia.genTipUnidad) | Validación: IsOptional, IsString, MaxLength(6) | Q23: Propuesta semántica | R23: Código del grupo de parámetros que define los tipos de unidad. Por defecto, TIUORG (tipo de unidad organizacional). | S23: Baja | T23: nombre + tipo + columnas vecinas + defecto | U23: ¿gen_tip_unidad es el código de la lista genérica a la que pertenece tip_unidad? | V23: Pendiente | AA23: =IF(OR(V23="Aprobada"),R23,IF(AND(OR(V23="Aprobada con ajuste",V23="Rechazada"),W23<>""),W23,""))
A24: C0023 | B24: Identidad y acceso | C24: auth | D24: dependencias | E24: 7 | F24: descripcion | G24: character varying(500) | H24: Sí | L24: No | M24: No | P24: Mapeada en auth-service/src/users/dependencia.entity.ts:88 (Dependencia.descripcion) | Validación: IsOptional, IsString, MaxLength(150), MaxLength(150, { message: 'La descripción no puede superar 150 caracteres' }), MaxLength(500) | Q24: Regla estructural | R24: Descripción del registro de dependencias. | S24: Media | T24: Convención de nombre de la columna. | V24: Pendiente | AA24: =IF(OR(V24="Aprobada"),R24,IF(AND(OR(V24="Aprobada con ajuste",V24="Rechazada"),W24<>""),W24,""))
A25: C0024 | B25: Identidad y acceso | C25: auth | D25: dependencias | E25: 7 | F25: activo | G25: boolean | H25: No | L25: No | M25: No | O25: idx_dependencias_activo | P25: Mapeada en auth-service/src/users/dependencia.entity.ts:91 (Dependencia.activo) | Validación: IsBoolean, IsOptional | Q25: Regla estructural | R25: Indica si el registro está activo. | S25: Media | T25: Convención de nombre de la columna. | V25: Pendiente | AA25: =IF(OR(V25="Aprobada"),R25,IF(AND(OR(V25="Aprobada con ajuste",V25="Rechazada"),W25<>""),W25,""))
A26: C0025 | B26: Identidad y acceso | C26: auth | D26: dependencias_cargos | E26: 30 | F26: activo | G26: boolean | H26: No | L26: No | M26: No | O26: idx_dep_cargos_activo | P26: Mapeada en auth-service/src/users/dependencia-cargo.entity.ts:29 (DependenciaCargo.activo) | Validación: IsBoolean, IsOptional | Q26: Regla estructural | R26: Indica si el registro está activo. | S26: Media | T26: Convención de nombre de la columna. | V26: Pendiente | AA26: =IF(OR(V26="Aprobada"),R26,IF(AND(OR(V26="Aprobada con ajuste",V26="Rechazada"),W26<>""),W26,""))
A27: C0026 | B27: Identidad y acceso | C27: auth | D27: documento_carpeta_digital | E27: 0 | F27: nombre | G27: character varying(255) | H27: No | L27: No | M27: No | P27: db/migrations/339_create_documento_carpeta_digital.sql:29: Metadatos del archivo | Validación: IsOptional, IsString | Q27: Código fuente | R27: Nombre del archivo del documento cargado en la Carpeta Digital. | S27: Media | T27: código: db/migrations/339_create_documento_carpeta_digital.sql:29 | U27: ¿nombre guarda el nombre original del archivo o un nombre descriptivo del documento? | V27: Pendiente | AA27: =IF(OR(V27="Aprobada"),R27,IF(AND(OR(V27="Aprobada con ajuste",V27="Rechazada"),W27<>""),W27,""))
A28: C0027 | B28: Identidad y acceso | C28: auth | D28: documento_carpeta_digital | E28: 0 | F28: categoria | G28: character varying(80) | H28: No | L28: No | M28: No | P28: Mapeada en auth-service/src/carpeta-digital/documento-carpeta-digital.entity.ts:43 (DocumentoCarpetaDigital.categoria) | Q28: Propuesta semántica | R28: Categoría del documento en la carpeta digital. Por defecto, otros. | S28: Media | T28: nombre + tipo + columnas vecinas + defecto | U28: ¿Qué categorías se usan y de qué catálogo provienen? | V28: Pendiente | AA28: =IF(OR(V28="Aprobada"),R28,IF(AND(OR(V28="Aprobada con ajuste",V28="Rechazada"),W28<>""),W28,""))
A29: C0028 | B29: Identidad y acceso | C29: auth | D29: documento_carpeta_digital | E29: 0 | F29: tipo_archivo | G29: character varying(40) | H29: Sí | L29: No | M29: No | P29: Mapeada en auth-service/src/carpeta-digital/documento-carpeta-digital.entity.ts:46 (DocumentoCarpetaDigital.tipoArchivo) | Q29: Propuesta semántica | R29: Tipo o formato del archivo subido (por ejemplo, pdf). | S29: Media | T29: nombre + tipo + columnas vecinas | U29: ¿Se guarda la extensión o el tipo MIME del archivo? | V29: Pendiente | AA29: =IF(OR(V29="Aprobada"),R29,IF(AND(OR(V29="Aprobada con ajuste",V29="Rechazada"),W29<>""),W29,""))
A30: C0029 | B30: Identidad y acceso | C30: auth | D30: documento_carpeta_digital | E30: 0 | F30: tamano_bytes | G30: bigint | H30: Sí | L30: No | M30: No | P30: Mapeada en auth-service/src/carpeta-digital/documento-carpeta-digital.entity.ts:49 (DocumentoCarpetaDigital.tamanoBytes) | Q30: Regla estructural | R30: Tamaño del archivo en bytes. | S30: Media | T30: Convención de nombre de la columna. | V30: Pendiente | AA30: =IF(OR(V30="Aprobada"),R30,IF(AND(OR(V30="Aprobada con ajuste",V30="Rechazada"),W30<>""),W30,""))
A31: C0030 | B31: Identidad y acceso | C31: auth | D31: documento_carpeta_digital | E31: 0 | F31: estado | G31: character varying(30) | H31: No | I31: CHECK | J31: pendiente, rechazado, validado, vencido | L31: Sí | M31: No | O31: idx_documento_cd_estado | P31: db/migrations/339_create_documento_carpeta_digital.sql:36: Estado de validación | Validación: IsOptional, IsString | Q31: Código fuente | R31: Estado de validación del documento. Valores permitidos: pendiente, validado, rechazado, vencido; por defecto pendiente. | S31: Alta | T31: código: db/migrations/339_create_documento_carpeta_digital.sql:36 | V31: Pendiente | AA31: =IF(OR(V31="Aprobada"),R31,IF(AND(OR(V31="Aprobada con ajuste",V31="Rechazada"),W31<>""),W31,""))
A32: C0031 | B32: Identidad y acceso | C32: auth | D32: documento_carpeta_digital | E32: 0 | F32: comentarios | G32: text | H32: Sí | L32: No | M32: No | P32: Mapeada en auth-service/src/carpeta-digital/documento-carpeta-digital.entity.ts:58 (DocumentoCarpetaDigital.comentarios) | Q32: Propuesta semántica | R32: Comentarios sobre el documento, como observaciones de la validación. | S32: Media | T32: nombre + tipo + columnas vecinas (estado, validado_por) | U32: ¿Los comentarios los escribe quien valida, quien sube el documento o ambos? | V32: Pendiente | AA32: =IF(OR(V32="Aprobada"),R32,IF(AND(OR(V32="Aprobada con ajuste",V32="Rechazada"),W32<>""),W32,""))
A33: C0032 | B33: Identidad y acceso | C33: auth | D33: documento_carpeta_digital | E33: 0 | F33: validado_por | G33: uuid | H33: Sí | L33: No | M33: No | P33: Mapeada en auth-service/src/carpeta-digital/documento-carpeta-digital.entity.ts:61 (DocumentoCarpetaDigital.validadoPor) | Q33: Regla estructural | R33: Usuario que realizó la validación. | S33: Media | T33: Convención de nombre de la columna. | V33: Pendiente | AA33: =IF(OR(V33="Aprobada"),R33,IF(AND(OR(V33="Aprobada con ajuste",V33="Rechazada"),W33<>""),W33,""))
A34: C0033 | B34: Identidad y acceso | C34: auth | D34: documento_carpeta_digital | E34: 0 | F34: fecha_validacion | G34: timestamp without time zone | H34: Sí | L34: No | M34: No | P34: Mapeada en auth-service/src/carpeta-digital/documento-carpeta-digital.entity.ts:64 (DocumentoCarpetaDigital.fechaValidacion) | Q34: Regla estructural | R34: Fecha de validación. | S34: Media | T34: Convención de nombre de la columna. | V34: Pendiente | AA34: =IF(OR(V34="Aprobada"),R34,IF(AND(OR(V34="Aprobada con ajuste",V34="Rechazada"),W34<>""),W34,""))
A35: C0034 | B35: Identidad y acceso | C35: auth | D35: documento_carpeta_digital | E35: 0 | F35: fecha_subida | G35: timestamp without time zone | H35: No | L35: No | M35: No | P35: db/migrations/339_create_documento_carpeta_digital.sql:42: Fechas | Q35: Código fuente | R35: Fecha y hora en que la persona cargó el documento; por defecto el momento de creación. | S35: Alta | T35: código: db/migrations/339_create_documento_carpeta_digital.sql:42 | V35: Pendiente | AA35: =IF(OR(V35="Aprobada"),R35,IF(AND(OR(V35="Aprobada con ajuste",V35="Rechazada"),W35<>""),W35,""))
A36: C0035 | B36: Identidad y acceso | C36: auth | D36: documento_carpeta_digital | E36: 0 | F36: fecha_vencimiento | G36: timestamp without time zone | H36: Sí | L36: No | M36: No | P36: Mapeada en auth-service/src/carpeta-digital/documento-carpeta-digital.entity.ts:70 (DocumentoCarpetaDigital.fechaVencimiento) | Q36: Regla estructural | R36: Fecha de vencimiento. | S36: Media | T36: Convención de nombre de la columna. | V36: Pendiente | AA36: =IF(OR(V36="Aprobada"),R36,IF(AND(OR(V36="Aprobada con ajuste",V36="Rechazada"),W36<>""),W36,""))
A37: C0036 | B37: Identidad y acceso | C37: auth | D37: festivos_colombia | E37: 18 | F37: fecha | G37: date | H37: No | I37: Única | L37: No | M37: No | O37: festivos_colombia_fecha_key, idx_auth_festivos_fecha | P37: Mapeada en travel-expenses-service/src/entities/festivo-colombia.entity.ts:21 (FestivoColombiaEntity.fecha) | Q37: Propuesta semántica | R37: Fecha del día festivo; es única en la tabla. | S37: Alta | T37: documentación de la entidad + restricción única | V37: Pendiente | AA37: =IF(OR(V37="Aprobada"),R37,IF(AND(OR(V37="Aprobada con ajuste",V37="Rechazada"),W37<>""),W37,""))
A38: C0037 | B38: Identidad y acceso | C38: auth | D38: festivos_colombia | E38: 18 | F38: descripcion | G38: character varying(150) | H38: No | L38: No | M38: No | P38: Mapeada en travel-expenses-service/src/entities/festivo-colombia.entity.ts:24 (FestivoColombiaEntity.descripcion) | Validación: IsOptional, IsString, Length(0, 255) | Q38: Regla estructural | R38: Descripción del registro de festivos_colombia. | S38: Media | T38: Convención de nombre de la columna. | V38: Pendiente | AA38: =IF(OR(V38="Aprobada"),R38,IF(AND(OR(V38="Aprobada con ajuste",V38="Rechazada"),W38<>""),W38,""))
A39: C0038 | B39: Identidad y acceso | C39: auth | D39: festivos_colombia | E39: 18 | F39: origen | G39: character varying(150) | H39: Sí | L39: No | M39: No | P39: Mapeada en auth-service/src/settings/festivo-colombia.entity.ts:26 (FestivoColombia.origen) | Validación: IsOptional, IsString, MaxLength(150) | Q39: Propuesta semántica | R39: Norma que establece el festivo. Por defecto, Ley 51/1983. | S39: Media | T39: nombre + tipo + columnas vecinas + defecto | U39: ¿origen guarda siempre la norma legal o también la fuente de carga? | V39: Pendiente | AA39: =IF(OR(V39="Aprobada"),R39,IF(AND(OR(V39="Aprobada con ajuste",V39="Rechazada"),W39<>""),W39,""))
A40: C0039 | B40: Identidad y acceso | C40: auth | D40: festivos_colombia | E40: 18 | F40: regla | G40: character varying(50) | H40: Sí | L40: No | M40: No | P40: Mapeada en auth-service/src/settings/festivo-colombia.entity.ts:35 (FestivoColombia.regla) | Validación: IsOptional, IsString, MaxLength(50) | Q40: Propuesta semántica | R40: Regla con la que se determina la fecha del festivo. Por defecto, fixed (fecha fija). | S40: Media | T40: nombre + tipo + columnas vecinas + defecto | U40: ¿Qué otros valores toma regla (por ejemplo, traslado al lunes o basado en Pascua)? | V40: Pendiente | AA40: =IF(OR(V40="Aprobada"),R40,IF(AND(OR(V40="Aprobada con ajuste",V40="Rechazada"),W40<>""),W40,""))
...

Sheet Uso en lógica
A1: Esquema | B1: Tabla | C1: Columna | D1: Objeto | E1: Tipo de objeto | F1: Líneas donde aparece la columna
A2: auth | B2: module | C2: code | D2: hiring.roles_del_modulo | E2: Vista
A3: auth | B3: module | C3: name | D3: hiring.roles_del_modulo | E3: Vista
A4: auth | B4: module | C4: is_active | D4: hiring.roles_del_modulo | E4: Vista
A5: auth | B5: permission | C5: code | D5: hiring.roles_del_modulo | E5: Vista
A6: auth | B6: permission | C6: name | D6: hiring.roles_del_modulo | E6: Vista
A7: auth | B7: permission | C7: is_active | D7: hiring.roles_del_modulo | E7: Vista
A8: auth | B8: personas | C8: num_identificacion | D8: trg_auth_personas_rund_document_immutable | E8: Trigger (UPDATE OF)
A9: auth | B9: personas | C9: num_identificacion | D9: control_interno.v_auditor_disponibilidad | E9: Vista
A10: auth | B10: personas | C10: tip_identificacion | D10: control_interno.v_auditor_disponibilidad | E10: Vista
A11: auth | B11: personas | C11: nom_largo | D11: control_interno.v_auditor_disponibilidad | E11: Vista
A12: auth | B12: personas | C12: nom_largo | D12: control_interno.v_auditorias_kanban_completo | E12: Vista
A13: auth | B13: personas | C13: dir_email | D13: control_interno.v_auditor_disponibilidad | E13: Vista
A14: auth | B14: personas | C14: dir_email | D14: control_interno.v_auditorias_kanban_completo | E14: Vista
A15: auth | B15: personas | C15: id_person | D15: control_interno.fn_registrar_cambio_estado_auditoria | E15: Función | F15: SELECT id_person INTO v_usuario_id
A16: auth | B16: personas | C16: id_person | D16: control_interno.fn_registrar_cambio_estado_plan_anual | E16: Función | F16: SELECT id_person INTO v_usuario_id
A17: auth | B17: personas | C17: id_person | D17: control_interno.v_auditor_disponibilidad | E17: Vista
A18: auth | B18: personas | C18: id_person | D18: control_interno.v_auditorias_kanban_completo | E18: Vista
A19: auth | B19: role | C19: code | D19: hiring.roles_del_modulo | E19: Vista
A20: auth | B20: role | C20: name | D20: hiring.roles_del_modulo | E20: Vista
A21: auth | B21: role | C21: type | D21: hiring.roles_del_modulo | E21: Vista
A22: auth | B22: role | C22: is_active | D22: hiring.roles_del_modulo | E22: Vista
A23: auth | B23: role_permissions | C23: is_active | D23: hiring.roles_del_modulo | E23: Vista
A24: academic_registration | B24: graduates | C24: full_name | D24: trg_validate_graduate_management_update | E24: Trigger (UPDATE OF)
A25: academic_registration | B25: graduates | C25: id_number | D25: trg_validate_graduate_management_update | E25: Trigger (UPDATE OF)
A26: academic_registration | B26: graduates | C26: email | D26: trg_validate_graduate_management_update | E26: Trigger (UPDATE OF)
A27: academic_registration | B27: graduates | C27: first_name | D27: trg_validate_graduate_management_update | E27: Trigger (UPDATE OF)
A28: academic_registration | B28: graduates | C28: last_name | D28: trg_validate_graduate_management_update | E28: Trigger (UPDATE OF)
A29: academic_work_plan | B29: Docente | C29: estado | D29: academic_work_plan.prevent_rund_document_change | E29: Función | F29: AND s.estado = 'PENDIENTE' AND j.estado = 'COMPLETADO' AND doc.estado = 'ACTIVO'
A30: academic_work_plan | B30: Documento | C30: nombre | D30: academic_registration.validate_graduate_management_update | E30: Función | F30: 'El nombre completo debe tener entre 5 y 150 caracteres y solo puede contener letras, espacios, apostrofes y guiones.' 'El nombre solo puede contener letras, espacios, apostrofes y guiones.'
A31: academic_work_plan | B31: Documento | C31: tipo | D31: control_interno.actualizar_contadores_documentos_informes | E31: Función | F31: -- Determinar el ID de la auditoría y el tipo de documento -- Determinar si es un informe basado en el tipo de documento
A32: academic_work_plan | B32: Documento | C32: estado | D32: academic_work_plan.prevent_rund_document_change | E32: Función | F32: AND s.estado = 'PENDIENTE' AND j.estado = 'COMPLETADO' AND doc.estado = 'ACTIVO'
A33: academic_work_plan | B33: periodo_academico | C33: codigo | D33: academic-schedule.reapuntar_grupos_por_equivalencia | E33: Función | F33: JOIN "academic-schedule".equivalencia_periodo e ON e.codigo_programacion = pp.codigo JOIN academic_work_plan.periodo_academico pa ON pa.codigo = e.codigo_periodo_academico
A34: academic_work_plan | B34: programa | C34: nombre | D34: control_interno.fn_configurar_actividad_auditorias_plan | E34: Función | F34: LOWER(a.nombre) LIKE '%auditoría%' OR LOWER(a.nombre) LIKE '%auditoria%' OR LOWER(a.nombre) LIKE '%programa de auditor%'
A35: academic_work_plan | B35: Rol | C35: nombre | D35: control_interno.fn_configurar_actividad_auditorias_plan | E35: Función | F35: LOWER(a.nombre) LIKE '%auditoría%' OR LOWER(a.nombre) LIKE '%auditoria%' OR LOWER(a.nombre) LIKE '%programa de auditor%'
A36: academic_work_plan | B36: RundDocumentoPerfil | C36: docente_id | D36: academic_work_plan.prevent_rund_document_change | E36: Función | F36: JOIN academic_work_plan."Docente" d ON d.id::text = j.docente_id::text
A37: academic_work_plan | B37: RundDocumentoPerfil | C37: estado | D37: academic_work_plan.prevent_rund_document_change | E37: Función | F37: AND s.estado = 'PENDIENTE' AND j.estado = 'COMPLETADO' AND doc.estado = 'ACTIVO'
A38: academic_work_plan | B38: RundExtraccionSugerencia | C38: campo | D38: academic_work_plan.prevent_rund_document_change | E38: Función | F38: AND s.campo = 'documentNumber'
A39: academic_work_plan | B39: RundExtraccionSugerencia | C39: valor | D39: academic_work_plan.prevent_rund_document_change | E39: Función | F39: AND regexp_replace(UPPER(BTRIM(s.valor)), '[^A-Z0-9]', '', 'g') =
A40: academic_work_plan | B40: RundExtraccionSugerencia | C40: estado | D40: academic_work_plan.prevent_rund_document_change | E40: Función | F40: AND s.estado = 'PENDIENTE' AND j.estado = 'COMPLETADO' AND doc.estado = 'ACTIVO'
...
